Workbook

Sheet Task Description
B2: Task Description
B4: Background:
B6: Catering is one of Edinburgh Airport's largest commercial revenue streams and plays a key role in the airport's overall financial performance. The Commercial team regularly reviews the performance of the catering estate to understand how outlets are trading, identify trends over time, and highlight opportunities to improve performance. The team uses dashboards to monitor key performance indicators and support commercial decision making. You have been provided with a dataset containing monthly sales and transaction data for a number of catering outlets across the airport (tab, RetailerData). You have also been provided with the total passenger numbers (tab, PassengerData)
B15: Your Task:
B17: Create an Output tab to produce any outcomes. Use formulas (e.g. do not copy paste as values from pviots) so we can see your thought process. Create an interactive dashboard in Excel, PowerBI (or both) that enables the Commercial team to monitor the performance of the catering estate. Your dashboard should allow users to quickly understand: - Overall catering performance - Individual outlet performance - Year on Year trends - YTD performance - Any other analysis you believe to be useful Alongside your dashboard, provide a short summary (max. 5 bullet points) outlining your key findings

Sheet Retail_Data_Original
A1: Category1 | B1: Outlet Name | C1: Category4 | D1: Year of Month Start Date | E1: Month of Month Start Date | F1: Unit Location | G1: Monthly Unit Size Meter Sq | H1: Transactions | I1: Total Sales
A2: Catering | B2: Gate Bistro | C2: Coffee | D2: 2024 | E2: December | F2: Central | G2: 398 | H2: 6930.5961 | I2: 144744.88
D3: 2025 | E3: January | F3: Central | G3: 398 | H3: 9413.0198 | I3: 228691.06
E4: February | F4: Central | G4: 398 | H4: 17939.191 | I4: 199814.15
E5: March | F5: Central | G5: 398 | H5: 14655.715 | I5: 333749.49
E6: April | F6: Central | G6: 398 | H6: 16830.057 | I6: 281233.75
E7: May | F7: Central | G7: 398 | H7: 26165.643 | I7: 379231.63
E8: June | F8: Central | G8: 398 | H8: 25846.403 | I8: 445530.49
E9: July | F9: Central | G9: 398 | H9: 22873.303 | I9: 399964.7
E10: August | F10: Central | G10: 398 | H10: 17669.771 | I10: 388876.27
E11: September | F11: Central | G11: 398 | H11: 24593.184 | I11: 399015.51
E12: October | F12: Central | G12: 398 | H12: 16708.588 | I12: 359711.42
E13: November | F13: Central | G13: 398 | H13: 20735.487 | I13: 295193.05
E14: December | F14: Central | G14: 398 | H14: 19333.355 | I14: 289865.47
D15: 2026 | E15: January | F15: Central | G15: 398 | H15: 16111.933 | I15: 292270.14
E16: February | F16: Central | G16: 398 | H16: 15861.79 | I16: 235071.51
E17: March | F17: Central | G17: 398 | H17: 13741.487 | I17: 292012.16
E18: April | F18: Central | G18: 398 | H18: 16814.743 | I18: 233875.49
E19: May | F19: Central | G19: 398 | H19: 21858.441 | I19: 305511.04
E20: June | F20: Central | G20: 398 | H20: 24825.179 | I20: 285397.27
B21: Terminal Kitchen | C21: Restaurants | D21: 2024 | E21: January | F21: East | G21: 300 | H21: 29433.737 | I21: 283173.55
E22: February | F22: East | G22: 300 | H22: 33870.637 | I22: 317239.04
E23: March | F23: East | G23: 300 | H23: 25452.317 | I23: 406520.3
E24: April | F24: East | G24: 300 | H24: 32054.895 | I24: 434253.39
E25: May | F25: East | G25: 300 | H25: 33878.082 | I25: 348854.71
E26: June | F26: East | G26: 300 | H26: 45283.913 | I26: 593538.52
E27: July | F27: East | G27: 300 | H27: 37922.194 | I27: 577074.16
E28: August | F28: East | G28: 300 | H28: 38398.113 | I28: 5161021.2
E29: September | F29: East | G29: 300 | H29: 44501.744 | I29: 513874.15
E30: October | F30: East | G30: 300 | H30: 39423.334 | I30: 393650.67
E31: November | F31: East | G31: 300 | H31: 27129.848 | I31: 352104.35
E32: December | F32: East | G32: 300 | H32: 30912.306 | I32: 495902.21
D33: 2025 | E33: January | F33: East | G33: 300 | H33: 24750.495 | I33: 340380.21
E34: February | F34: East | G34: 300 | H34: 26229.901 | I34: 252247.12
E35: March | F35: East | G35: 300 | H35: 23377.561 | I35: 300082.7
E36: April | F36: East | G36: 300 | H36: 36302.335 | I36: 374099.27
E37: May | F37: East | G37: 300 | H37: 27423.5 | I37: 544318.32
E38: June | F38: East | G38: 300 | H38: 35533.293 | I38: 378073.99
E39: July | F39: East | G39: 300 | H39: 38449.315 | I39: 667406
E40: August | F40: East | G40: 300 | H40: 42503.813 | I40: 435838.28
...

Sheet Passenger_Data_Original
B2: Month | C2: Jan | D2: Feb | E2: Mar | F2: Apr | G2: May | H2: Jun | I2: Jul | J2: Aug | K2: Sep | L2: Oct | M2: Nov | N2: Dec
B3: 2024Actual | C3: 895441 | D3: 948465 | E3: 1117311 | F3: 1284638 | G3: 1495297 | H3: 1561422 | I3: 1628915 | J3: 1618153 | K3: 1529718 | L3: 1468168 | M3: 1091165 | N3: 1153914
B4: 2025Actual | C4: 950595 | D4: 1016868 | E4: 1191178 | F4: 1393786 | G4: 1576429 | H4: 1643722 | I4: 1783169 | J4: 1770479 | K4: 1628996 | L4: 1609903 | M4: 1193998 | N4: 1222096
B5: 2026Actual | C5: 1017320 | D5: 1071937 | E5: 1274309 | F5: 1465123 | G5: 1655765 | H5: 1709032 | I5: 0 | J5: 0 | K5: 0 | L5: 0 | M5: 0 | N5: 0

Sheet Retail_Data
A1: Retail Data — One Row per Outlet per Month
A3: date | B3: year | C3: month_number | D3: month | E3: category_group | F3: outlet_name | G3: outlet_type | H3: unit_location | I3: unit_size_sqm | J3: transactions | K3: total_sales | L3: sales_per_transaction | M3: sales_per_sqm | N3: common_12_month_period | O3: data_quality_flag
A4: 45627 | B4: 2024 | C4: 12 | D4: Dec | E4: Catering | F4: Gate Bistro | G4: Coffee | H4: Central | I4: 398 | J4: 6930.5961 | K4: 144744.88 | L4: =IFERROR(K4/J4,"") -> 20.884911 | M4: =IFERROR(K4/I4,"") -> 363.6806 | N4: =IF(AND(A4>=DATE(2025,6,1),A4<=DATE(2026,5,1)),"Yes","No") -> No | O4: =IF(L4="","Check",IF(L4>50,"Review","Normal")) -> Normal
A5: 45658 | B5: 2025 | C5: 1 | D5: Jan | E5: Catering | F5: Gate Bistro | G5: Coffee | H5: Central | I5: 398 | J5: 9413.0198 | K5: 228691.06 | L5: =IFERROR(K5/J5,"") -> 24.295185 | M5: =IFERROR(K5/I5,"") -> 574.60065 | N5: =IF(AND(A5>=DATE(2025,6,1),A5<=DATE(2026,5,1)),"Yes","No") -> No | O5: =IF(L5="","Check",IF(L5>50,"Review","Normal")) -> Normal
A6: 45689 | B6: 2025 | C6: 2 | D6: Feb | E6: Catering | F6: Gate Bistro | G6: Coffee | H6: Central | I6: 398 | J6: 17939.191 | K6: 199814.15 | L6: =IFERROR(K6/J6,"") -> 11.138414 | M6: =IFERROR(K6/I6,"") -> 502.04559 | N6: =IF(AND(A6>=DATE(2025,6,1),A6<=DATE(2026,5,1)),"Yes","No") -> No | O6: =IF(L6="","Check",IF(L6>50,"Review","Normal")) -> Normal
A7: 45717 | B7: 2025 | C7: 3 | D7: Mar | E7: Catering | F7: Gate Bistro | G7: Coffee | H7: Central | I7: 398 | J7: 14655.715 | K7: 333749.49 | L7: =IFERROR(K7/J7,"") -> 22.772651 | M7: =IFERROR(K7/I7,"") -> 838.56656 | N7: =IF(AND(A7>=DATE(2025,6,1),A7<=DATE(2026,5,1)),"Yes","No") -> No | O7: =IF(L7="","Check",IF(L7>50,"Review","Normal")) -> Normal
A8: 45748 | B8: 2025 | C8: 4 | D8: Apr | E8: Catering | F8: Gate Bistro | G8: Coffee | H8: Central | I8: 398 | J8: 16830.057 | K8: 281233.75 | L8: =IFERROR(K8/J8,"") -> 16.710208 | M8: =IFERROR(K8/I8,"") -> 706.61747 | N8: =IF(AND(A8>=DATE(2025,6,1),A8<=DATE(2026,5,1)),"Yes","No") -> No | O8: =IF(L8="","Check",IF(L8>50,"Review","Normal")) -> Normal
A9: 45778 | B9: 2025 | C9: 5 | D9: May | E9: Catering | F9: Gate Bistro | G9: Coffee | H9: Central | I9: 398 | J9: 26165.643 | K9: 379231.63 | L9: =IFERROR(K9/J9,"") -> 14.493496 | M9: =IFERROR(K9/I9,"") -> 952.84328 | N9: =IF(AND(A9>=DATE(2025,6,1),A9<=DATE(2026,5,1)),"Yes","No") -> No | O9: =IF(L9="","Check",IF(L9>50,"Review","Normal")) -> Normal
A10: 45809 | B10: 2025 | C10: 6 | D10: Jun | E10: Catering | F10: Gate Bistro | G10: Coffee | H10: Central | I10: 398 | J10: 25846.403 | K10: 445530.49 | L10: =IFERROR(K10/J10,"") -> 17.237621 | M10: =IFERROR(K10/I10,"") -> 1119.4234 | N10: =IF(AND(A10>=DATE(2025,6,1),A10<=DATE(2026,5,1)),"Yes","No") -> Yes | O10: =IF(L10="","Check",IF(L10>50,"Review","Normal")) -> Normal
A11: 45839 | B11: 2025 | C11: 7 | D11: Jul | E11: Catering | F11: Gate Bistro | G11: Coffee | H11: Central | I11: 398 | J11: 22873.303 | K11: 399964.7 | L11: =IFERROR(K11/J11,"") -> 17.486093 | M11: =IFERROR(K11/I11,"") -> 1004.9364 | N11: =IF(AND(A11>=DATE(2025,6,1),A11<=DATE(2026,5,1)),"Yes","No") -> Yes | O11: =IF(L11="","Check",IF(L11>50,"Review","Normal")) -> Normal
A12: 45870 | B12: 2025 | C12: 8 | D12: Aug | E12: Catering | F12: Gate Bistro | G12: Coffee | H12: Central | I12: 398 | J12: 17669.771 | K12: 388876.27 | L12: =IFERROR(K12/J12,"") -> 22.007998 | M12: =IFERROR(K12/I12,"") -> 977.07605 | N12: =IF(AND(A12>=DATE(2025,6,1),A12<=DATE(2026,5,1)),"Yes","No") -> Yes | O12: =IF(L12="","Check",IF(L12>50,"Review","Normal")) -> Normal
A13: 45901 | B13: 2025 | C13: 9 | D13: Sep | E13: Catering | F13: Gate Bistro | G13: Coffee | H13: Central | I13: 398 | J13: 24593.184 | K13: 399015.51 | L13: =IFERROR(K13/J13,"") -> 16.224638 | M13: =IFERROR(K13/I13,"") -> 1002.5515 | N13: =IF(AND(A13>=DATE(2025,6,1),A13<=DATE(2026,5,1)),"Yes","No") -> Yes | O13: =IF(L13="","Check",IF(L13>50,"Review","Normal")) -> Normal
A14: 45931 | B14: 2025 | C14: 10 | D14: Oct | E14: Catering | F14: Gate Bistro | G14: Coffee | H14: Central | I14: 398 | J14: 16708.588 | K14: 359711.42 | L14: =IFERROR(K14/J14,"") -> 21.528535 | M14: =IFERROR(K14/I14,"") -> 903.79754 | N14: =IF(AND(A14>=DATE(2025,6,1),A14<=DATE(2026,5,1)),"Yes","No") -> Yes | O14: =IF(L14="","Check",IF(L14>50,"Review","Normal")) -> Normal
A15: 45962 | B15: 2025 | C15: 11 | D15: Nov | E15: Catering | F15: Gate Bistro | G15: Coffee | H15: Central | I15: 398 | J15: 20735.487 | K15: 295193.05 | L15: =IFERROR(K15/J15,"") -> 14.236128 | M15: =IFERROR(K15/I15,"") -> 741.69108 | N15: =IF(AND(A15>=DATE(2025,6,1),A15<=DATE(2026,5,1)),"Yes","No") -> Yes | O15: =IF(L15="","Check",IF(L15>50,"Review","Normal")) -> Normal
... A125: 46174 | B125: 2026 | C125: 6 | D125: Jun | E125: Catering | F125: Terminal Kitchen | G125: Restaurants | H125: East | I125: 300 | J125: 46790.245 | K125: 551662.2 | L125: =IFERROR(K125/J125,"") -> 11.790111 | M125: =IFERROR(K125/I125,"") -> 1838.874 | N125: =IF(AND(A125>=DATE(2025,6,1),A125<=DATE(2026,5,1)),"Yes","No") -> No | O125: =IF(L125="","Check",IF(L125>50,"Review","Normal")) -> Normal

Sheet Passenger_Data
A1: Passenger Data — One Row per Month
A3: date | B3: year | C3: month_number | D3: month | E3: passenger_amount
A4: 45292 | B4: 2024 | C4: 1 | D4: Jan | E4: 895441
A5: 45323 | B5: 2024 | C5: 2 | D5: Feb | E5: 948465
A6: 45352 | B6: 2024 | C6: 3 | D6: Mar | E6: 1117311
A7: 45383 | B7: 2024 | C7: 4 | D7: Apr | E7: 1284638
A8: 45413 | B8: 2024 | C8: 5 | D8: May | E8: 1495297
A9: 45444 | B9: 2024 | C9: 6 | D9: Jun | E9: 1561422
A10: 45474 | B10: 2024 | C10: 7 | D10: Jul | E10: 1628915
A11: 45505 | B11: 2024 | C11: 8 | D11: Aug | E11: 1618153
A12: 45536 | B12: 2024 | C12: 9 | D12: Sep | E12: 1529718
A13: 45566 | B13: 2024 | C13: 10 | D13: Oct | E13: 1468168
A14: 45597 | B14: 2024 | C14: 11 | D14: Nov | E14: 1091165
A15: 45627 | B15: 2024 | C15: 12 | D15: Dec | E15: 1153914
... A33: 46174 | B33: 2026 | C33: 6 | D33: Jun | E33: 1709032

Sheet Output
A1: Catering Commercial Performance — Formula Output
A2: Change the year, as-of date and outlet below. The KPI blocks, outlet table and monthly trends update from formulas.
A4: Controls | K4: Outlet YTD Comparison
A5: Selected Year | B5: 2025 | K5: Outlet | L5: YTD Sales | M5: Prior YTD Sales | N5: Sales YoY | O5: YTD Transactions | P5: Avg Transaction Value | Q5: Sales per Sqm | R5: Estate Sales Share
A6: As-of Date | B6: 46357 | K6: Gate Bistro | L6: =SUMIFS(Retail_Data!$K:$K,Retail_Data!$F:$F,$K6,Retail_Data!$A:$A,">="&DATE($B$5,1,1),Retail_Data!$A:$A,"<="&$B$6) -> 5645014.6 | M6: =SUMIFS(Retail_Data!$K:$K,Retail_Data!$F:$F,$K6,Retail_Data!$A:$A,">="&DATE($B$5-1,1,1),Retail_Data!$A:$A,"<="&EDATE($B$6,-12)) -> 4145621.9 | N6: =IFERROR(L6/M6-1,"") -> 0.36168102 | O6: =SUMIFS(Retail_Data!$J:$J,Retail_Data!$F:$F,$K6,Retail_Data!$A:$A,">="&DATE($B$5,1,1),Retail_Data!$A:$A,"<="&$B$6) -> 341977.29 | P6: =IFERROR(L6/O6,"") -> 16.506987 | Q6: =IFERROR(L6/_xludf.MAXIFS(Retail_Data!$I:$I,Retail_Data!$F:$F,$K6),"") | R6: =IFERROR(L6/$B$11,"") -> 0.12919372
A7: Selected Outlet | B7: Terminal Kitchen | K7: North Kitchen | L7: =SUMIFS(Retail_Data!$K:$K,Retail_Data!$F:$F,$K7,Retail_Data!$A:$A,">="&DATE($B$5,1,1),Retail_Data!$A:$A,"<="&$B$6) -> 23332271 | M7: =SUMIFS(Retail_Data!$K:$K,Retail_Data!$F:$F,$K7,Retail_Data!$A:$A,">="&DATE($B$5-1,1,1),Retail_Data!$A:$A,"<="&EDATE($B$6,-12)) -> 29211239 | N7: =IFERROR(L7/M7-1,"") -> -0.20125705 | O7: =SUMIFS(Retail_Data!$J:$J,Retail_Data!$F:$F,$K7,Retail_Data!$A:$A,">="&DATE($B$5,1,1),Retail_Data!$A:$A,"<="&$B$6) -> 1624831.7 | P7: =IFERROR(L7/O7,"") -> 14.359808 | Q7: =IFERROR(L7/_xludf.MAXIFS(Retail_Data!$I:$I,Retail_Data!$F:$F,$K7),"") | R7: =IFERROR(L7/$B$11,"") -> 0.53399026
K8: Oak Coffee Bar | L8: =SUMIFS(Retail_Data!$K:$K,Retail_Data!$F:$F,$K8,Retail_Data!$A:$A,">="&DATE($B$5,1,1),Retail_Data!$A:$A,"<="&$B$6) -> 5236409.8 | M8: =SUMIFS(Retail_Data!$K:$K,Retail_Data!$F:$F,$K8,Retail_Data!$A:$A,">="&DATE($B$5-1,1,1),Retail_Data!$A:$A,"<="&EDATE($B$6,-12)) -> 5806943.9 | N8: =IFERROR(L8/M8-1,"") -> -0.09825032 | O8: =SUMIFS(Retail_Data!$J:$J,Retail_Data!$F:$F,$K8,Retail_Data!$A:$A,">="&DATE($B$5,1,1),Retail_Data!$A:$A,"<="&$B$6) -> 695671.52 | P8: =IFERROR(L8/O8,"") -> 7.5271297 | Q8: =IFERROR(L8/_xludf.MAXIFS(Retail_Data!$I:$I,Retail_Data!$F:$F,$K8),"") | R8: =IFERROR(L8/$B$11,"") -> 0.11984225
A9: Overall Catering YTD Performance | F9: Selected Outlet YTD Performance | K9: Sky Deli | L9: =SUMIFS(Retail_Data!$K:$K,Retail_Data!$F:$F,$K9,Retail_Data!$A:$A,">="&DATE($B$5,1,1),Retail_Data!$A:$A,"<="&$B$6) -> 2476930.4 | M9: =SUMIFS(Retail_Data!$K:$K,Retail_Data!$F:$F,$K9,Retail_Data!$A:$A,">="&DATE($B$5-1,1,1),Retail_Data!$A:$A,"<="&EDATE($B$6,-12)) -> 1619302.6 | N9: =IFERROR(L9/M9-1,"") -> 0.52962785 | O9: =SUMIFS(Retail_Data!$J:$J,Retail_Data!$F:$F,$K9,Retail_Data!$A:$A,">="&DATE($B$5,1,1),Retail_Data!$A:$A,"<="&$B$6) -> 113900.34 | P9: =IFERROR(L9/O9,"") -> 21.746471 | Q9: =IFERROR(L9/_xludf.MAXIFS(Retail_Data!$I:$I,Retail_Data!$F:$F,$K9),"") | R9: =IFERROR(L9/$B$11,"") -> 0.056687867
A10: Metric | B10: Current YTD | C10: Prior YTD | D10: YoY Change | F10: Metric | G10: Current YTD | H10: Prior YTD | I10: YoY Change | K10: Terminal Kitchen | L10: =SUMIFS(Retail_Data!$K:$K,Retail_Data!$F:$F,$K10,Retail_Data!$A:$A,">="&DATE($B$5,1,1),Retail_Data!$A:$A,"<="&$B$6) -> 7003562.8 | M10: =SUMIFS(Retail_Data!$K:$K,Retail_Data!$F:$F,$K10,Retail_Data!$A:$A,">="&DATE($B$5-1,1,1),Retail_Data!$A:$A,"<="&EDATE($B$6,-12)) -> 14983698 | N10: =IFERROR(L10/M10-1,"") -> -0.53258782 | O10: =SUMIFS(Retail_Data!$J:$J,Retail_Data!$F:$F,$K10,Retail_Data!$A:$A,">="&DATE($B$5,1,1),Retail_Data!$A:$A,"<="&$B$6) -> 522054.95 | P10: =IFERROR(L10/O10,"") -> 13.415375 | Q10: =IFERROR(L10/_xludf.MAXIFS(Retail_Data!$I:$I,Retail_Data!$F:$F,$K10),"") | R10: =IFERROR(L10/$B$11,"") -> 0.16028591
A11: Total Sales | B11: =SUMIFS(Retail_Data!$K:$K,Retail_Data!$A:$A,">="&DATE($B$5,1,1),Retail_Data!$A:$A,"<="&$B$6) -> 43694188 | C11: =SUMIFS(Retail_Data!$K:$K,Retail_Data!$A:$A,">="&DATE($B$5-1,1,1),Retail_Data!$A:$A,"<="&EDATE($B$6,-12)) -> 55766804 | D11: =IFERROR(B11/C11-1,"") -> -0.21648391 | F11: Total Sales | G11: =SUMIFS(Retail_Data!$K:$K,Retail_Data!$F:$F,$B$7,Retail_Data!$A:$A,">="&DATE($B$5,1,1),Retail_Data!$A:$A,"<="&$B$6) -> 7003562.8 | H11: =SUMIFS(Retail_Data!$K:$K,Retail_Data!$F:$F,$B$7,Retail_Data!$A:$A,">="&DATE($B$5-1,1,1),Retail_Data!$A:$A,"<="&EDATE($B$6,-12)) -> 14983698 | I11: =IFERROR(G11/H11-1,"") -> -0.53258782
A12: Transactions | B12: =SUMIFS(Retail_Data!$J:$J,Retail_Data!$A:$A,">="&DATE($B$5,1,1),Retail_Data!$A:$A,"<="&$B$6) -> 3298435.8 | C12: =SUMIFS(Retail_Data!$J:$J,Retail_Data!$A:$A,">="&DATE($B$5-1,1,1),Retail_Data!$A:$A,"<="&EDATE($B$6,-12)) -> 3963822.3 | D12: =IFERROR(B12/C12-1,"") -> -0.16786488 | F12: Transactions | G12: =SUMIFS(Retail_Data!$J:$J,Retail_Data!$F:$F,$B$7,Retail_Data!$A:$A,">="&DATE($B$5,1,1),Retail_Data!$A:$A,"<="&$B$6) -> 522054.95 | H12: =SUMIFS(Retail_Data!$J:$J,Retail_Data!$F:$F,$B$7,Retail_Data!$A:$A,">="&DATE($B$5-1,1,1),Retail_Data!$A:$A,"<="&EDATE($B$6,-12)) -> 788174.7 | I12: =IFERROR(G12/H12-1,"") -> -0.33764056
A13: Passengers | B13: =SUMIFS(Passenger_Data!$E:$E,Passenger_Data!$A:$A,">="&DATE($B$5,1,1),Passenger_Data!$A:$A,"<="&$B$6) -> 25174705 | C13: =SUMIFS(Passenger_Data!$E:$E,Passenger_Data!$A:$A,">="&DATE($B$5-1,1,1),Passenger_Data!$A:$A,"<="&EDATE($B$6,-12)) -> 32773826 | D13: =IFERROR(B13/C13-1,"") -> -0.23186554 | F13: Average Transaction Value | G13: =IFERROR(G11/G12,"") -> 13.415375 | H13: =IFERROR(H11/H12,"") -> 19.01063 | I13: =IFERROR(G13/H13-1,"") -> -0.29432245
A14: Average Transaction Value | B14: =IFERROR(B11/B12,"") -> 13.246942 | C14: =IFERROR(C11/C12,"") -> 14.068946 | D14: =IFERROR(B14/C14-1,"") -> -0.058426845 | F14: Sales per Square Metre | G14: =IFERROR(G11/_xludf.MAXIFS(Retail_Data!$I:$I,Retail_Data!$F:$F,$B$7),"") | H14: =IFERROR(H11/_xludf.MAXIFS(Retail_Data!$I:$I,Retail_Data!$F:$F,$B$7),"") | I14: =IFERROR(G14/H14-1,"")
A15: Transactions per 1,000 Passengers | B15: =IFERROR((B12/B13)*1000,"") -> 131.02182 | C15: =IFERROR((C12/C13)*1000,"") -> 120.94475 | D15: =IFERROR(B15/C15-1,"") -> 0.083319606 | F15: Share of Estate Sales | G15: =IFERROR(G11/$B$11,"") -> 0.16028591 | H15: =IFERROR(H11/$C$11,"") -> 0.26868489 | I15: =IFERROR(G15/H15-1,"") -> -0.40344278
A18: Monthly Performance, YoY and YTD Trend
A19: date | B19: year | C19: month_number | D19: month | E19: active_outlets | F19: total_sales | G19: total_transactions | H19: passenger_amount | I19: sales_per_transaction | J19: sales_per_1000_passengers | K19: transactions_per_1000_passengers | L19: prior_year_sales | M19: sales_yoy_pct | N19: ytd_sales | O19: ytd_sales_yoy_pct
A20: 45292 | B20: 2024 | C20: 1 | D20: Jan | E20: =COUNTIF(Retail_Data!$A:$A,A20) -> 3 | F20: =SUMIF(Retail_Data!$A:$A,A20,Retail_Data!$K:$K) -> 1285199.1 | G20: =SUMIF(Retail_Data!$A:$A,A20,Retail_Data!$J:$J) -> 108130.44 | H20: =SUMIF(Passenger_Data!$A:$A,A20,Passenger_Data!$E:$E) -> 895441 | I20: =IFERROR(F20/G20,"") -> 11.885637 | J20: =IFERROR((F20/H20)*1000,"") -> 1435.2694 | K20: =IFERROR((G20/H20)*1000,"") -> 120.75663 | L20: =SUMIF(Retail_Data!$A:$A,EDATE(A20,-12),Retail_Data!$K:$K) -> 0 | M20: =IFERROR(F20/L20-1,"") | N20: =SUMIFS(Retail_Data!$K:$K,Retail_Data!$A:$A,">="&DATE(B20,1,1),Retail_Data!$A:$A,"<="&A20) -> 1285199.1 | O20: =IFERROR(N20/SUMIFS(Retail_Data!$K:$K,Retail_Data!$A:$A,">="&DATE(B20-1,1,1),Retail_Data!$A:$A,"<="&EDATE(A20,-12))-1,"")
A21: 45323 | B21: 2024 | C21: 2 | D21: Feb | E21: =COUNTIF(Retail_Data!$A:$A,A21) -> 3 | F21: =SUMIF(Retail_Data!$A:$A,A21,Retail_Data!$K:$K) -> 1191468.2 | G21: =SUMIF(Retail_Data!$A:$A,A21,Retail_Data!$J:$J) -> 97993.858 | H21: =SUMIF(Passenger_Data!$A:$A,A21,Passenger_Data!$E:$E) -> 948465 | I21: =IFERROR(F21/G21,"") -> 12.158601 | J21: =IFERROR((F21/H21)*1000,"") -> 1256.2068 | K21: =IFERROR((G21/H21)*1000,"") -> 103.31837 | L21: =SUMIF(Retail_Data!$A:$A,EDATE(A21,-12),Retail_Data!$K:$K) -> 0 | M21: =IFERROR(F21/L21-1,"") | N21: =SUMIFS(Retail_Data!$K:$K,Retail_Data!$A:$A,">="&DATE(B21,1,1),Retail_Data!$A:$A,"<="&A21) -> 2476667.3 | O21: =IFERROR(N21/SUMIFS(Retail_Data!$K:$K,Retail_Data!$A:$A,">="&DATE(B21-1,1,1),Retail_Data!$A:$A,"<="&EDATE(A21,-12))-1,"")
A22: 45352 | B22: 2024 | C22: 3 | D22: Mar | E22: =COUNTIF(Retail_Data!$A:$A,A22) -> 3 | F22: =SUMIF(Retail_Data!$A:$A,A22,Retail_Data!$K:$K) -> 1320726.6 | G22: =SUMIF(Retail_Data!$A:$A,A22,Retail_Data!$J:$J) -> 109682.85 | H22: =SUMIF(Passenger_Data!$A:$A,A22,Passenger_Data!$E:$E) -> 1117311 | I22: =IFERROR(F22/G22,"") -> 12.041323 | J22: =IFERROR((F22/H22)*1000,"") -> 1182.0582 | K22: =IFERROR((G22/H22)*1000,"") -> 98.166803 | L22: =SUMIF(Retail_Data!$A:$A,EDATE(A22,-12),Retail_Data!$K:$K) -> 0 | M22: =IFERROR(F22/L22-1,"") | N22: =SUMIFS(Retail_Data!$K:$K,Retail_Data!$A:$A,">="&DATE(B22,1,1),Retail_Data!$A:$A,"<="&A22) -> 3797394 | O22: =IFERROR(N22/SUMIFS(Retail_Data!$K:$K,Retail_Data!$A:$A,">="&DATE(B22-1,1,1),Retail_Data!$A:$A,"<="&EDATE(A22,-12))-1,"")
A23: 45383 | B23: 2024 | C23: 4 | D23: Apr | E23: =COUNTIF(Retail_Data!$A:$A,A23) -> 3 | F23: =SUMIF(Retail_Data!$A:$A,A23,Retail_Data!$K:$K) -> 1632518.8 | G23: =SUMIF(Retail_Data!$A:$A,A23,Retail_Data!$J:$J) -> 143500.12 | H23: =SUMIF(Passenger_Data!$A:$A,A23,Passenger_Data!$E:$E) -> 1284638 | I23: =IFERROR(F23/G23,"") -> 11.376428 | J23: =IFERROR((F23/H23)*1000,"") -> 1270.8006 | K23: =IFERROR((G23/H23)*1000,"") -> 111.70471 | L23: =SUMIF(Retail_Data!$A:$A,EDATE(A23,-12),Retail_Data!$K:$K) -> 0 | M23: =IFERROR(F23/L23-1,"") | N23: =SUMIFS(Retail_Data!$K:$K,Retail_Data!$A:$A,">="&DATE(B23,1,1),Retail_Data!$A:$A,"<="&A23) -> 5429912.8 | O23: =IFERROR(N23/SUMIFS(Retail_Data!$K:$K,Retail_Data!$A:$A,">="&DATE(B23-1,1,1),Retail_Data!$A:$A,"<="&EDATE(A23,-12))-1,"")
A24: 45413 | B24: 2024 | C24: 5 | D24: May | E24: =COUNTIF(Retail_Data!$A:$A,A24) -> 3 | F24: =SUMIF(Retail_Data!$A:$A,A24,Retail_Data!$K:$K) -> 2066828.9 | G24: =SUMIF(Retail_Data!$A:$A,A24,Retail_Data!$J:$J) -> 199121.35 | H24: =SUMIF(Passenger_Data!$A:$A,A24,Passenger_Data!$E:$E) -> 1495297 | I24: =IFERROR(F24/G24,"") -> 10.379745 | J24: =IFERROR((F24/H24)*1000,"") -> 1382.2197 | K24: =IFERROR((G24/H24)*1000,"") -> 133.16508 | L24: =SUMIF(Retail_Data!$A:$A,EDATE(A24,-12),Retail_Data!$K:$K) -> 0 | M24: =IFERROR(F24/L24-1,"") | N24: =SUMIFS(Retail_Data!$K:$K,Retail_Data!$A:$A,">="&DATE(B24,1,1),Retail_Data!$A:$A,"<="&A24) -> 7496741.7 | O24: =IFERROR(N24/SUMIFS(Retail_Data!$K:$K,Retail_Data!$A:$A,">="&DATE(B24-1,1,1),Retail_Data!$A:$A,"<="&EDATE(A24,-12))-1,"")
A25: 45444 | B25: 2024 | C25: 6 | D25: Jun | E25: =COUNTIF(Retail_Data!$A:$A,A25) -> 3 | F25: =SUMIF(Retail_Data!$A:$A,A25,Retail_Data!$K:$K) -> 2551417.7 | G25: =SUMIF(Retail_Data!$A:$A,A25,Retail_Data!$J:$J) -> 165114.42 | H25: =SUMIF(Passenger_Data!$A:$A,A25,Passenger_Data!$E:$E) -> 1561422 | I25: =IFERROR(F25/G25,"") -> 15.452422 | J25: =IFERROR((F25/H25)*1000,"") -> 1634.0347 | K25: =IFERROR((G25/H25)*1000,"") -> 105.74618 | L25: =SUMIF(Retail_Data!$A:$A,EDATE(A25,-12),Retail_Data!$K:$K) -> 0 | M25: =IFERROR(F25/L25-1,"") | N25: =SUMIFS(Retail_Data!$K:$K,Retail_Data!$A:$A,">="&DATE(B25,1,1),Retail_Data!$A:$A,"<="&A25) -> 10048159 | O25: =IFERROR(N25/SUMIFS(Retail_Data!$K:$K,Retail_Data!$A:$A,">="&DATE(B25-1,1,1),Retail_Data!$A:$A,"<="&EDATE(A25,-12))-1,"")
A26: 45474 | B26: 2024 | C26: 7 | D26: Jul | E26: =COUNTIF(Retail_Data!$A:$A,A26) -> 3 | F26: =SUMIF(Retail_Data!$A:$A,A26,Retail_Data!$K:$K) -> 2006916.7 | G26: =SUMIF(Retail_Data!$A:$A,A26,Retail_Data!$J:$J) -> 181236.23 | H26: =SUMIF(Passenger_Data!$A:$A,A26,Passenger_Data!$E:$E) -> 1628915 | I26: =IFERROR(F26/G26,"") -> 11.073485 | J26: =IFERROR((F26/H26)*1000,"") -> 1232.0573 | K26: =IFERROR((G26/H26)*1000,"") -> 111.26193 | L26: =SUMIF(Retail_Data!$A:$A,EDATE(A26,-12),Retail_Data!$K:$K) -> 0 | M26: =IFERROR(F26/L26-1,"") | N26: =SUMIFS(Retail_Data!$K:$K,Retail_Data!$A:$A,">="&DATE(B26,1,1),Retail_Data!$A:$A,"<="&A26) -> 12055076 | O26: =IFERROR(N26/SUMIFS(Retail_Data!$K:$K,Retail_Data!$A:$A,">="&DATE(B26-1,1,1),Retail_Data!$A:$A,"<="&EDATE(A26,-12))-1,"")
A27: 45505 | B27: 2024 | C27: 8 | D27: Aug | E27: =COUNTIF(Retail_Data!$A:$A,A27) -> 3 | F27: =SUMIF(Retail_Data!$A:$A,A27,Retail_Data!$K:$K) -> 6760699.9 | G27: =SUMIF(Retail_Data!$A:$A,A27,Retail_Data!$J:$J) -> 163062.14 | H27: =SUMIF(Passenger_Data!$A:$A,A27,Passenger_Data!$E:$E) -> 1618153 | I27: =IFERROR(F27/G27,"") -> 41.460879 | J27: =IFERROR((F27/H27)*1000,"") -> 4178.035 | K27: =IFERROR((G27/H27)*1000,"") -> 100.77054 | L27: =SUMIF(Retail_Data!$A:$A,EDATE(A27,-12),Retail_Data!$K:$K) -> 0 | M27: =IFERROR(F27/L27-1,"") | N27: =SUMIFS(Retail_Data!$K:$K,Retail_Data!$A:$A,">="&DATE(B27,1,1),Retail_Data!$A:$A,"<="&A27) -> 18815776 | O27: =IFERROR(N27/SUMIFS(Retail_Data!$K:$K,Retail_Data!$A:$A,">="&DATE(B27-1,1,1),Retail_Data!$A:$A,"<="&EDATE(A27,-12))-1,"")
A28: 45536 | B28: 2024 | C28: 9 | D28: Sep | E28: =COUNTIF(Retail_Data!$A:$A,A28) -> 3 | F28: =SUMIF(Retail_Data!$A:$A,A28,Retail_Data!$K:$K) -> 2056802.3 | G28: =SUMIF(Retail_Data!$A:$A,A28,Retail_Data!$J:$J) -> 151017.55 | H28: =SUMIF(Passenger_Data!$A:$A,A28,Passenger_Data!$E:$E) -> 1529718 | I28: =IFERROR(F28/G28,"") -> 13.619625 | J28: =IFERROR((F28/H28)*1000,"") -> 1344.5631 | K28: =IFERROR((G28/H28)*1000,"") -> 98.722477 | L28: =SUMIF(Retail_Data!$A:$A,EDATE(A28,-12),Retail_Data!$K:$K) -> 0 | M28: =IFERROR(F28/L28-1,"") | N28: =SUMIFS(Retail_Data!$K:$K,Retail_Data!$A:$A,">="&DATE(B28,1,1),Retail_Data!$A:$A,"<="&A28) -> 20872578 | O28: =IFERROR(N28/SUMIFS(Retail_Data!$K:$K,Retail_Data!$A:$A,">="&DATE(B28-1,1,1),Retail_Data!$A:$A,"<="&EDATE(A28,-12))-1,"")
A29: 45566 | B29: 2024 | C29: 10 | D29: Oct | E29: =COUNTIF(Retail_Data!$A:$A,A29) -> 3 | F29: =SUMIF(Retail_Data!$A:$A,A29,Retail_Data!$K:$K) -> 1751863.7 | G29: =SUMIF(Retail_Data!$A:$A,A29,Retail_Data!$J:$J) -> 166627.51 | H29: =SUMIF(Passenger_Data!$A:$A,A29,Passenger_Data!$E:$E) -> 1468168 | I29: =IFERROR(F29/G29,"") -> 10.513652 | J29: =IFERROR((F29/H29)*1000,"") -> 1193.2311 | K29: =IFERROR((G29/H29)*1000,"") -> 113.49349 | L29: =SUMIF(Retail_Data!$A:$A,EDATE(A29,-12),Retail_Data!$K:$K) -> 0 | M29: =IFERROR(F29/L29-1,"") | N29: =SUMIFS(Retail_Data!$K:$K,Retail_Data!$A:$A,">="&DATE(B29,1,1),Retail_Data!$A:$A,"<="&A29) -> 22624442 | O29: =IFERROR(N29/SUMIFS(Retail_Data!$K:$K,Retail_Data!$A:$A,">="&DATE(B29-1,1,1),Retail_Data!$A:$A,"<="&EDATE(A29,-12))-1,"")
A30: 45597 | B30: 2024 | C30: 11 | D30: Nov | E30: =COUNTIF(Retail_Data!$A:$A,A30) -> 3 | F30: =SUMIF(Retail_Data!$A:$A,A30,Retail_Data!$K:$K) -> 1786598.9 | G30: =SUMIF(Retail_Data!$A:$A,A30,Retail_Data!$J:$J) -> 120149.1 | H30: =SUMIF(Passenger_Data!$A:$A,A30,Passenger_Data!$E:$E) -> 1091165 | I30: =IFERROR(F30/G30,"") -> 14.869848 | J30: =IFERROR((F30/H30)*1000,"") -> 1637.3315 | K30: =IFERROR((G30/H30)*1000,"") -> 110.11085 | L30: =SUMIF(Retail_Data!$A:$A,EDATE(A30,-12),Retail_Data!$K:$K) -> 0 | M30: =IFERROR(F30/L30-1,"") | N30: =SUMIFS(Retail_Data!$K:$K,Retail_Data!$A:$A,">="&DATE(B30,1,1),Retail_Data!$A:$A,"<="&A30) -> 24411041 | O30: =IFERROR(N30/SUMIFS(Retail_Data!$K:$K,Retail_Data!$A:$A,">="&DATE(B30-1,1,1),Retail_Data!$A:$A,"<="&EDATE(A30,-12))-1,"")
A31: 45627 | B31: 2024 | C31: 12 | D31: Dec | E31: =COUNTIF(Retail_Data!$A:$A,A31) -> 4 | F31: =SUMIF(Retail_Data!$A:$A,A31,Retail_Data!$K:$K) -> 2083333.6 | G31: =SUMIF(Retail_Data!$A:$A,A31,Retail_Data!$J:$J) -> 142003.73 | H31: =SUMIF(Passenger_Data!$A:$A,A31,Passenger_Data!$E:$E) -> 1153914 | I31: =IFERROR(F31/G31,"") -> 14.670978 | J31: =IFERROR((F31/H31)*1000,"") -> 1805.4497 | K31: =IFERROR((G31/H31)*1000,"") -> 123.06266 | L31: =SUMIF(Retail_Data!$A:$A,EDATE(A31,-12),Retail_Data!$K:$K) -> 0 | M31: =IFERROR(F31/L31-1,"") | N31: =SUMIFS(Retail_Data!$K:$K,Retail_Data!$A:$A,">="&DATE(B31,1,1),Retail_Data!$A:$A,"<="&A31) -> 26494374 | O31: =IFERROR(N31/SUMIFS(Retail_Data!$K:$K,Retail_Data!$A:$A,">="&DATE(B31-1,1,1),Retail_Data!$A:$A,"<="&EDATE(A31,-12))-1,"")
... A49: 46174 | B49: 2026 | C49: 6 | D49: Jun | E49: =COUNTIF(Retail_Data!$A:$A,A49) -> 4 | F49: =SUMIF(Retail_Data!$A:$A,A49,Retail_Data!$K:$K) -> 2833991.2 | G49: =SUMIF(Retail_Data!$A:$A,A49,Retail_Data!$J:$J) -> 239802.4 | H49: =SUMIF(Passenger_Data!$A:$A,A49,Passenger_Data!$E:$E) -> 1709032 | I49: =IFERROR(F49/G49,"") -> 11.818027 | J49: =IFERROR((F49/H49)*1000,"") -> 1658.2435 | K49: =IFERROR((G49/H49)*1000,"") -> 140.31475 | L49: =SUMIF(Retail_Data!$A:$A,EDATE(A49,-12),Retail_Data!$K:$K) -> 3092476.6 | M49: =IFERROR(F49/L49-1,"") -> -0.083585251 | N49: =SUMIFS(Retail_Data!$K:$K,Retail_Data!$A:$A,">="&DATE(B49,1,1),Retail_Data!$A:$A,"<="&A49) -> 14421758 | O49: =IFERROR(N49/SUMIFS(Retail_Data!$K:$K,Retail_Data!$A:$A,">="&DATE(B49-1,1,1),Retail_Data!$A:$A,"<="&EDATE(A49,-12))-1,"") -> 0.087986464

Sheet Data_Notes
A1: Edinburgh Airport Catering Challenge — Data Notes
F2: Years | G2: Outlets
A3: Item | B3: Explanation | C3: Value / Setting | D3: Why it matters | F3: 2024 | G3: Gate Bistro
A4: Retail table grain | B4: One row per outlet per month. | D4: Supports overall and individual outlet analysis. | F4: 2025 | G4: North Kitchen
A5: Passenger table grain | B5: One row per month. | D5: Avoids duplicating passenger totals across outlet rows. | F5: 2026 | G5: Oak Coffee Bar
A6: Output tab | B6: Formula-driven analysis showing overall performance, outlet performance, YoY and YTD outcomes. | D6: Meets the brief's requirement to show thought process. | G6: Sky Deli
A7: As-of date | B7: The YTD calculations use the date selected on the Output tab. | D7: Allows a fair current-year versus prior-year comparison. | G7: Terminal Kitchen
A8: High-sales observation | B8: Terminal Kitchen, August 2024 sales of £5,161,021.20 were retained and flagged for review. | D8: The original source value creates an unusually high sales-per-transaction result.
A9: Passenger field warning | B9: Do not sum passenger figures from the original combined table. | D9: The same passenger figure was repeated for every outlet in a month.
A10: Recommended Power BI model | B10: Relate Retail_Data and Passenger_Data to a separate Date table. | D10: Prevents double counting and supports YoY/YTD measures.
